Workbook
Name Cc: Cover!$H$3:$H$3
Name period: Cover!$H$2:$H$2
Name ticker: Cover!$C$8:$C$8

Sheet Cover
C4: Financial Analysis and Presentation
C6: =TODAY() -> 45641
C7: Amazon.com Inc.
C8: NASDAQ:AMZN
C10: Team 12:
C11: Alessandro FRULLANI
C12: Felipe MIGUEL BERTI
C13: Giada SIMBARI
C14: Ivan SERDAROV
C15: Maria Jose Castañeda

Sheet Summary
B1: Amazon.com Inc. (AMZN)
G3: Forecast
B4: Income Statement | D4: 2021 | E4: 2022 | F4: 2023 | G4: 2024E | H4: 2025E | I4: 2026E | J4: 2027E | K4: 2028E
B6: Revenue | D6: =Model!C6 -> 469822 | E6: =Model!D6 -> 513983 | F6: =Model!E6 -> 574785 | G6: =Model!F6 -> 638043.37 | H6: =Model!G6 -> 701356.64 | I6: =Model!H6 -> 766881.78 | J6: =Model!I6 -> 839695.3 | K6: =Model!J6 -> 920707.8
B7: Gross Profit | D7: =Model!C8 -> 197478 | E7: =Model!D8 -> 225152 | F7: =Model!E8 -> 270046 | G7: =Model!F8 -> 311073.89 | H7: =Model!G8 -> 336651.19 | I7: =Model!H8 -> 375772.07 | J7: =Model!I8 -> 419847.65 | K7: =Model!J8 -> 469560.98
B8: EBITDA | D8: =IS!AP94 -> 73945 | E8: =IS!AU94 -> 37363 | F8: =IS!AZ94 -> 86453 | G8: =IS!BE94 -> 115373.54 | H8: =IS!BJ94 -> 133193.95 | I8: =IS!BK94 -> 157977.65 | J8: =IS!BL94 -> 172977.23 | K8: =IS!BM94 -> 194269.34
B9: Operating Income | D9: =Model!C11 -> 24879 | E9: =Model!D11 -> 12248 | F9: =Model!E11 -> 36852 | G9: =Model!F11 -> 65238.255 | H9: =Model!G11 -> 73642.447 | I9: =Model!H11 -> 79755.705 | J9: =Model!I11 -> 83129.834 | K9: =Model!J11 -> 91150.072
B10: Net Income | D10: =Model!C16 -> 33364 | E10: =Model!D16 -> -2722 | F10: =Model!E16 -> 30425 | G10: =Model!F16 -> 52898.854 | H10: =Model!G16 -> 56515.318 | I10: =Model!H16 -> 61189.497 | J10: =Model!I16 -> 63682.491 | K10: =Model!J16 -> 69826.479
B11: EPS | D11: =Model!C19 -> 3.2404817 | E11: =Model!D19 -> -0.26715085 | F11: =Model!E19 -> 2.8998284 | G11: =Model!F19 -> 4.9354003 | H11: =Model!G19 -> 5.2159961 | I11: =Model!H19 -> 5.5855314 | J11: =Model!I19 -> 5.7501121 | K11: =Model!J19 -> 6.2372916
B13: Growth (% YoY)
B14: Revenue | D14: =IS!AP46 -> 0.21695367 | E14: =E6/ABS(D6)-1 -> 0.093995173 | F14: =F6/ABS(E6)-1 -> 0.11829574 | G14: =G6/ABS(F6)-1 -> 0.11005571 | H14: =H6/ABS(G6)-1 -> 0.099230361 | I14: =I6/ABS(H6)-1 -> 0.093426267 | J14: =J6/ABS(I6)-1 -> 0.094947516 | K14: =K6/ABS(J6)-1 -> 0.096478448
B15: Gross Profit | D15: =IS!AP48 -> 0.29275909 | E15: =E7/ABS(D7)-1 -> 0.14013713 | F15: =F7/ABS(E7)-1 -> 0.19939419 | G15: =G7/ABS(F7)-1 -> 0.15192928 | H15: =H7/ABS(G7)-1 -> 0.082222571 | I15: =I7/ABS(H7)-1 -> 0.11620598 | J15: =J7/ABS(I7)-1 -> 0.11729338 | K15: =K7/ABS(J7)-1 -> 0.11840802
B16: Operating Income | D16: =IS!AP55 -> 0.086466658 | E16: =E9/ABS(D9)-1 -> -0.50769725 | F16: =F9/ABS(E9)-1 -> 2.0088178 | G16: =G9/ABS(F9)-1 -> 0.77027719 | H16: =H9/ABS(G9)-1 -> 0.12882307 | I16: =I9/ABS(H9)-1 -> 0.083012684 | J16: =J9/ABS(I9)-1 -> 0.042305809 | K16: =K9/ABS(J9)-1 -> 0.096478448
B17: Net Income | D17: =IS!AP62 -> 0.56410857 | E17: =E10/ABS(D10)-1 -> -1.0815849 | F17: =F10/ABS(E10)-1 -> 10.177443 | G17: =G10/ABS(F10)-1 -> 0.73866407 | H17: =H10/ABS(G10)-1 -> 0.068365635 | I17: =I10/ABS(H10)-1 -> 0.082706402 | J17: =J10/ABS(I10)-1 -> 0.040742194 | K17: =K10/ABS(J10)-1 -> 0.096478448
B18: EPS | D18: =IS!AP63 -> 0.55023923 | E18: =E11/ABS(D11)-1 -> -1.0824417 | F18: =F11/ABS(E11)-1 -> 9.854648 | G18: =G11/ABS(F11)-1 -> 0.70196286 | H18: =H11/ABS(G11)-1 -> 0.056853712 | I18: =I11/ABS(H11)-1 -> 0.070846542 | J18: =J11/ABS(I11)-1 -> 0.029465529 | K18: =K11/ABS(J11)-1 -> 0.084725218
B20: Profitability (%)
B21: Gross Margin | D21: =D7/D6 -> 0.42032514 | E21: =E7/E6 -> 0.4380534 | F21: =F7/F6 -> 0.46982089 | G21: =G7/G6 -> 0.48754349 | H21: =H7/H6 -> 0.48 | I21: =I7/I6 -> 0.49 | J21: =J7/J6 -> 0.5 | K21: =K7/K6 -> 0.51
B22: EBITDA Margin | D22: =D8/D6 -> 0.15738939 | E22: =E8/E6 -> 0.072693066 | F22: =F8/F6 -> 0.15040928 | G22: =G8/G6 -> 0.18082398 | H22: =H8/H6 -> 0.18990902 | I22: =I8/I6 -> 0.206 | J22: =J8/J6 -> 0.206 | K22: =K8/K6 -> 0.211
B23: Operating Margin | D23: =D9/D6 -> 0.052954098 | E23: =E9/E6 -> 0.023829582 | F23: =F9/F6 -> 0.064114408 | G23: =G9/G6 -> 0.10224737 | H23: =H9/H6 -> 0.105 | I23: =I9/I6 -> 0.104 | J23: =J9/J6 -> 0.099 | K23: =K9/K6 -> 0.099
B24: Net Profit Margin | D24: =D10/D6 -> 0.071014129 | E24: =E10/E6 -> -0.005295895 | F24: =F10/F6 -> 0.052932836 | G24: =G10/G6 -> 0.082907929 | H24: =H10/H6 -> 0.08058 | I24: =I10/I6 -> 0.07979 | J24: =J10/J6 -> 0.07584 | K24: =K10/K6 -> 0.07584
B25: Return on Equity | D25: =Ratios!C45 -> 0.29249425 | E25: =Ratios!D45 -> -0.019805582 | F25: =Ratios!E45 -> 0.17812836 | G25: =Ratios!F45 -> 0.22307237 | H25: =Ratios!G45 -> 0.18918224 | I25: =Ratios!H45 -> 0.17042761 | J25: =Ratios!I45 -> 0.1510376 | K25: =Ratios!J45 -> 0.14289881
B26: ROIC | D26: =Ratios!C47 -> 0.16048767 | E26: =Ratios!D47 -> -0.0079813361 | F26: =Ratios!E47 -> 0.098945665 | G26: =Ratios!F47 -> 0.14030744 | H26: =Ratios!G47 -> 0.13557033 | I26: =Ratios!H47 -> 0.12666076 | J26: =Ratios!I47 -> 0.11655192 | K26: =Ratios!J47 -> 0.11346814
B28: Leverage
B30: Degree of Operational Leverage | D30: =Ratios!C51 -> 8.6342798 | E30: =Ratios!D51 -> -59.536137 | F30: =Ratios!E51 -> 16.086679 | G30: =Ratios!F51 -> 2.8122308 | H30: =Ratios!G51 -> 2.0043467 | I30: =Ratios!H51 -> 0.8906203 | J30: =Ratios!I51 -> 0.4560314 | K30: =Ratios!J51 -> 1
B31: Degree of Financial Leverage | D31: =Ratios!C52 -> 1.2095018 | E31: =Ratios!D52 -> 0.88728071 | F31: =Ratios!E52 -> 0.85493114 | G31: =Ratios!F52 -> 0.74807952 | H31: =Ratios!G52 -> 1.0252438 | I31: =Ratios!H52 -> 0.99397976 | J31: =Ratios!I52 -> 0.94094894 | K31: =Ratios!J52 -> 1
B32: Degree of Combined Leverage | D32: =Ratios!C53 -> 10.443177 | E32: =Ratios!D53 -> -52.825266 | F32: =Ratios!E53 -> 13.753003 | G32: =Ratios!F53 -> 2.1037723 | H32: =Ratios!G53 -> 2.054944 | I32: =Ratios!H53 -> 0.88525855 | J32: =Ratios!I53 -> 0.42910226 | K32: =Ratios!J53 -> 1
B33: Debt -to-Equity | D33: =Ratios!C54 -> 0.84194727 | E33: =Ratios!D54 -> 0.95942976 | F33: =Ratios!E54 -> 0.67175728 | G33: =Ratios!F54 -> 0.50878464 | H33: =Ratios!G54 -> 0.46034304 | I33: =Ratios!H54 -> 0.40418507 | J33: =Ratios!I54 -> 0.36166564 | K33: =Ratios!J54 -> 0.32572294
B35: Cash Flow
B36: Dividends per Share | D36: - | E36: - | F36: - | G36: - | H36: - | I36: - | J36: - | K36: -
B37: Free Cash Flow to the Firm | D37: =CF!AP46 -> -9069 | E37: =CF!AU46 -> -11569 | F37: =CF!AZ46 -> 36813 | G37: =CF!BE46 -> 32516.456 | H37: =CF!BJ46 -> 42853.701 | I37: =CF!BK46 -> 56636.788 | J37: =CF!BL46 -> 57614.428 | K37: =CF!BM46 -> 62528.289

Sheet Assumptions + Estimates
B1: Amazon.com Inc. (AMZN)
C3: Assumptions | F3: Estimates
C4: 2021 | D4: 2022 | E4: 2023 | F4: 45382 | G4: 45473 | H4: 45565 | I4: 45657 | J4: 2024 | K4: 45747 | L4: 45838 | M4: 45930 | N4: 46022 | O4: 2025 | P4: 2026 | Q4: 2027 | R4: 2028
B5: USA GDP Growth | C5: 0.058 | D5: 0.0194 | E5: 0.0254 | J5: 0.027 | O5: 0.02 | P5: 0.02 | Q5: 0.02 | R5: 0.018
B6: Unemployment Rate (USA) | C6: 0.067 | D6: 0.035 | E6: 0.037 | J6: 0.044 | O6: 0.044 | P6: 0.043 | Q6: 0.042 | R6: 0.042
B7: PCE Inflation (USA) | C7: 0.047 | D7: 0.08 | E7: 0.041 | J7: 0.026 | O7: 0.021 | P7: 0.02 | Q7: 0.02 | R7: 0.02
B8: Fed Funds Rate | C8: 0.0008 | D8: 0.0168 | E8: 0.0503 | J8: 0.044 | O8: 0.034 | P8: 0.029 | Q8: 0.029 | R8: 0.029
B10: Revenue Growth | C10: 2021 | D10: 2022 | E10: 2023 | F10: 45382 | G10: 45473 | H10: 45565 | I10: 45657 | J10: 2024 | K10: 45747 | L10: 45838 | M10: 45930 | N10: 46022 | O10: 2025 | P10: 2026 | Q10: 2027 | R10: 2028
B11: Online Stores | C11: =IS!AP39 -> 0.12529073 | D11: =IS!AU39 -> -0.0093256783 | E11: =IS!AZ39 -> 0.053944474 | F11: 0.02 | G11: 0.02 | H11: 0.07 | I11: 0.08 | J11: =IS!BE102/IS!$AZ8-1 -> 0.050602789 | K11: 0.05 | L11: 0.05 | M11: 0.05 | N11: 0.05 | O11: =IS!BJ102/IS!BE102-1 -> 0.058535599 | P11: 0.05 | Q11: 0.05 | R11: 0.05
B12: Physical Stores | C12: =IS!AP40 -> 0.052453156 | D12: =IS!AU40 -> 0.11057101 | E12: =IS!AZ40 -> 0.056267468 | F12: 0.04 | G12: 0.04 | H12: 0.06 | I12: 0.06 | J12: =IS!BE103/IS!$AZ9-1 -> 0.050095856 | K12: 0.05 | L12: 0.05 | M12: 0.05 | N12: 0.05 | O12: =IS!BJ103/IS!BE103-1 -> 0.050632686 | P12: 0.05 | Q12: 0.05 | R12: 0.05
B13: Third-Party Seller Services | C13: =IS!AP41 -> 0.28505538 | D13: =IS!AU41 -> 0.13882708 | E13: =IS!AZ41 -> 0.1897533 | F13: 0.1 | G13: 0.1 | H13: 0.15 | I13: 0.15 | J13: =IS!BE104/IS!$AZ10-1 -> 0.12781126 | K13: 0.1 | L13: 0.1 | M13: 0.1 | N13: 0.1 | O13: =IS!BJ104/IS!BE104-1 -> 0.098843827 | P13: 0.1 | Q13: 0.1 | R13: 0.1
B14: Subscription Services | C14: =IS!AP42 -> 0.26028484 | D14: =IS!AU42 -> 0.10859985 | E14: =IS!AZ42 -> 0.1417173 | F14: 0.1 | G14: 0.1 | H14: 0.14 | I14: 0.12 | J14: =IS!BE105/IS!$AZ11-1 -> 0.11533388 | K14: 0.1 | L14: 0.1 | M14: 0.1 | N14: 0.1 | O14: =IS!BJ105/IS!BE105-1 -> 0.093062505 | P14: 0.1 | Q14: 0.1 | R14: 0.1
B15: Advertising Services | C15: =IS!AP43 -> 1.5267596 | D15: =IS!AU43 -> 0.21113607 | E15: =IS!AZ43 -> 0.24290522 | F15: 0.18 | G15: 0.18 | H15: 0.2 | I15: 0.2 | J15: =IS!BE106/IS!$AZ12-1 -> 0.19139044 | K15: 0.18 | L15: 0.18 | M15: 0.18 | N15: 0.18 | O15: =IS!BJ106/IS!BE106-1 -> 0.19058464 | P15: 0.15 | Q15: 0.15 | R15: 0.15
B16: AWS | C16: =IS!AP44 -> 0.37099405 | D16: =IS!AU44 -> 0.28767564 | E16: =IS!AZ44 -> 0.13310278 | F16: 0.15 | G16: 0.18 | H16: 0.2 | I16: 0.2 | J16: =IS!BE107/IS!$AZ13-1 -> 0.18335666 | K16: 0.18 | L16: 0.18 | M16: 0.18 | N16: 0.18 | O16: =IS!BJ107/IS!BE107-1 -> 0.18015453 | P16: 0.15 | Q16: 0.15 | R16: 0.15
B17: Other | C17: =IS!AP45 -> -0.76205577 | D17: =IS!AU45 -> 0.95174632 | E17: =IS!AZ45 -> 0.16741229 | F17: 0.05 | G17: 0.05 | H17: 0.05 | I17: 0.05 | J17: =IS!BE108/IS!$AZ14-1 -> 0.05 | K17: 0.05 | L17: 0.05 | M17: 0.05 | N17: 0.05 | O17: =IS!BJ108/IS!BE108-1 -> 0.06172852 | P17: 0.05 | Q17: 0.05 | R17: 0.05
B18: Total Revenue | C18: =IS!AP46 -> 0.21695367 | D18: =IS!AU46 -> 0.093995173 | E18: =IS!AZ46 -> 0.11829574 | J18: =IS!BE109/IS!$AZ15-1 -> 0.10637153 | O18: =IS!BJ109/IS!BE109-1 -> 0.10289076 | P18: =IS!BK15/IS!BJ15-1 -> 0.093426267 | Q18: =IS!BL15/IS!BK15-1 -> 0.094947516 | R18: =IS!BM15/IS!BL15-1 -> 0.096478448
B20: Net Income Margin | C20: =Ratios!C44 -> 0.071014129 | D20: =Ratios!D44 -> -0.005295895 | E20: =Ratios!E44 -> 0.052932836 | F20: 0.05 | G20: 0.07 | H20: 0.09 | I20: 0.08 | J20: =IS!BE110/IS!BE109 -> 0.07375304 | K20: 0.08 | L20: 0.08 | M20: 0.08 | N20: 0.08 | O20: 0.08 | P20: 0.08 | Q20: 0.076 | R20: 0.076
B22: % of Revenue | C22: 2021 | D22: 2022 | E22: 2023 | F22: 45382 | G22: 45473 | H22: 45565 | I22: 45657 | J22: 2024 | K22: 45747 | L22: 45838 | M22: 45930 | N22: 46022 | O22: 2025 | P22: 2026 | Q22: 2027 | R22: 2028
B23: Total Cost of Goods Sold | C23: =IS!AP74 -> 0.57967486 | D23: =IS!AU74 -> 0.5619466 | E23: =IS!AZ74 -> 0.53017911 | J23: 0.53 | O23: 0.52 | P23: 0.51 | Q23: 0.5 | R23: 0.49
B25: Fulfillment | C25: =IS!AP76 -> 0.15987119 | D25: =IS!AU76 -> 0.16401126 | E25: =IS!AZ76 -> 0.15765721 | J25: 0.154 | O25: 0.154 | P25: 0.15 | Q25: 0.15 | R25: 0.15
B26: Technology and Content | C26: =IS!AP77 -> 0.11930476 | D26: =IS!AU77 -> 0.14244245 | E26: =IS!AZ77 -> 0.14896353 | J26: 0.13 | O26: 0.13 | P26: 0.13 | Q26: 0.14 | R26: 0.15
B27: Marketing | C27: =IS!AP78 -> 0.069283686 | D27: =IS!AU78 -> 0.082177815 | E27: =IS!AZ78 -> 0.077194081 | J27: 0.07 | O27: 0.07 | P27: 0.08 | Q27: 0.08 | R27: 0.08
B28: General & Administrative | C28: =IS!AP79 -> 0.018779453 | D28: =IS!AU79 -> 0.023135006 | E28: =IS!AZ79 -> 0.020557252 | J28: 0.02 | O28: 0.02 | P28: 0.025 | Q28: 0.03 | R28: 0.03
B29: Other Operating Expenses (Income) | C29: =IS!AP80 -> 0.00013196487 | D29: =IS!AU80 -> 0.0024572797 | E29: =IS!AZ80 -> 0.001334412 | J29: 0.001 | O29: 0.001 | P29: 0.001 | Q29: 0.001 | R29: 0.001
B32: Interest Income | C32: =IS!AP83 -> 0.00095355262 | D32: =IS!AU83 -> 0.0019241882 | E32: =IS!AZ83 -> 0.0051306141 | J32: 0.005 | O32: 0.005 | P32: 0.005 | Q32: 0.005 | R32: 0.005
B33: Interest Expense | C33: =IS!AP84 -> -0.0038503944 | D33: =IS!AU84 -> -0.0046052107 | E33: =IS!AZ84 -> -0.005535983 | J33: -0.01 | O33: -0.01 | P33: -0.01 | Q33: -0.01 | R33: -0.01
B34: Other Income, Net | C34: =IS!AP85 -> 0.031145838 | D34: =IS!AU85 -> -0.032697579 | E34: =IS!AZ85 -> 0.0016319145 | J34: 0.002 | O34: 0.002 | P34: 0.002 | Q34: 0.002 | R34: 0.002
B39: Effective Tax Rate | C39: =IS!AP90 -> 0.12557993 | D39: =IS!AU90 -> 0.54194744 | E39: =IS!AZ90 -> 0.18957851 | J39: 0.21 | O39: 0.21 | P39: 0.21 | Q39: 0.21 | R39: 0.21
B41: Depreciation | C41: =CF!AP9/IS!AP15 -> 0.072997859 | D41: =CF!AU9/IS!AU15 -> 0.080666092 | E41: =CF!AZ9/IS!AZ15 -> 0.084662961 | J41: 0.09 | O41: 0.095 | P41: 0.1 | Q41: 0.105 | R41: 0.11
B42: Purchases of PP&E | C42: =CF!AP22/IS!AP15 -> -0.12994921 | D42: =CF!AU22/IS!AU15 -> -0.12382705 | E42: =CF!AZ22/IS!AZ15 -> -0.09173691 | J42: -0.1 | O42: -0.12 | P42: -0.12 | Q42: -0.12 | R42: -0.12

Sheet Model
B1: Amazon.com Inc. (AMZN)
F3: Forecast
B4: Income Statement | C4: 2021 | D4: 2022 | E4: 2023 | F4: 2024E | G4: 2025E | H4: 2026E | I4: 2027E | J4: 2028E
B6: Revenue | C6: =IS!AP15 -> 469822 | D6: =IS!AU15 -> 513983 | E6: =IS!AZ15 -> 574785 | F6: =IS!BE15 -> 638043.37 | G6: =IS!BJ15 -> 701356.64 | H6: =IS!BK15 -> 766881.78 | I6: =IS!BL15 -> 839695.3 | J6: =IS!BM15 -> 920707.8
B7: Cost of Goods Sold | C7: =IS!AP16 -> 272344 | D7: =IS!AU16 -> 288831 | E7: =IS!AZ16 -> 304739 | F7: =IS!BE16 -> 326969.48 | G7: =IS!BJ16 -> 364705.45 | H7: =IS!BK16 -> 391109.71 | I7: =IS!BL16 -> 419847.65 | J7: =IS!BM16 -> 451146.82
B8: Gross Profit | C8: =C6-C7 -> 197478 | D8: =D6-D7 -> 225152 | E8: =E6-E7 -> 270046 | F8: =F6-F7 -> 311073.89 | G8: =G6-G7 -> 336651.19 | H8: =H6-H7 -> 375772.07 | I8: =I6-I7 -> 419847.65 | J8: =J6-J7 -> 469560.98
B10: Selling, General, and Admin. Expenses | C10: =SUM(IS!AP18:AP22) -> 172599 | D10: =SUM(IS!AU18:AU22) -> 212904 | E10: =SUM(IS!AZ18:AZ22) -> 233194 | F10: =SUM(IS!BE18:BE22) -> 245835.64 | G10: =SUM(IS!BJ18:BJ22) -> 263008.74 | H10: =SUM(IS!BK18:BK22) -> 296016.37 | I10: =SUM(IS!BL18:BL22) -> 336717.81 | J10: =SUM(IS!BM18:BM22) -> 378410.9
B11: Operating Income | C11: =C8-C10 -> 24879 | D11: =D8-D10 -> 12248 | E11: =E8-E10 -> 36852 | F11: =F8-F10 -> 65238.255 | G11: =G8-G10 -> 73642.447 | H11: =H8-H10 -> 79755.705 | I11: =I8-I10 -> 83129.834 | J11: =J8-J10 -> 91150.072
B13: Net Interest Expense | C13: =-SUM(IS!AP25:AP27) -> -13272 | D13: =-SUM(IS!AU25:AU27) -> 18184 | E13: =-SUM(IS!AZ25:AZ27) -> -705 | F13: =-SUM(IS!BE25:BE27) -> 1688.6291 | G13: =-SUM(IS!BJ25:BJ27) -> 2104.0699 | H13: =-SUM(IS!BK25:BK27) -> 2300.6453 | I13: =-SUM(IS!BL25:BL27) -> 2519.0859 | J13: =-SUM(IS!BM25:BM27) -> 2762.1234
B14: Income Tax Expense | C14: =-IS!AP29 -> 4791 | D14: =-IS!AU29 -> -3217 | E14: =-IS!AZ29 -> 7120 | F14: =-IS!BE29 -> 10569.771 | G14: =-IS!BJ29 -> 15023.059 | H14: =-IS!BK29 -> 16265.562 | I14: =-IS!BL29 -> 16928.257 | J14: =-IS!BM29 -> 18561.469
B15: After-tax items | C15: =IS!AP30 -> 4 | D15: =IS!AU30 -> -3 | E15: =IS!AZ30 -> -12 | F15: =IS!BE30 -> -81 | G15: =IS!BJ30 -> 0 | H15: =IS!BK30 -> 0 | I15: =IS!BL30 -> 0 | J15: =IS!BM30 -> 0
B16: Net Income | C16: =C11-C13-C14+C15 -> 33364 | D16: =D11-D13-D14+D15 -> -2722 | E16: =E11-E13-E14+E15 -> 30425 | F16: =F11-F13-F14+F15 -> 52898.854 | G16: =G11-G13-G14+G15 -> 56515.318 | H16: =H11-H13-H14+H15 -> 61189.497 | I16: =I11-I13-I14+I15 -> 63682.491 | J16: =J11-J13-J14+J15 -> 69826.479
B18: Weighted Avg Diluted Shares Outstanding | C18: =IS!AP36 -> 10296 | D18: =IS!AU36 -> 10189 | E18: =IS!AZ36 -> 10492 | F18: =IS!BE36 -> 10718.25 | G18: =IS!BJ36 -> 10835 | H18: =IS!BK36 -> 10955 | I18: =IS!BL36 -> 11075 | J18: =IS!BM36 -> 11195
B19: Diluted Earnings Per Share (GAAP) | C19: =C16/C18 -> 3.2404817 | D19: =D16/D18 -> -0.26715085 | E19: =E16/E18 -> 2.8998284 | F19: =F16/F18 -> 4.9354003 | G19: =G16/G18 -> 5.2159961 | H19: =H16/H18 -> 5.5855314 | I19: =I16/I18 -> 5.7501121 | J19: =J16/J18 -> 6.2372916
F21: Forecast
B22: Balance Sheet | C22: 2021 | D22: 2022 | E22: 2023 | F22: 2024E | G22: 2025E | H22: 2026E | I22: 2027E | J22: 2028E
B24: Cash & Equivalents | C24: =BS!AP8+BS!AP9 -> 96049 | D24: =BS!AU8+BS!AU9 -> 70026 | E24: =BS!AZ8+BS!AZ9 -> 86780 | F24: =BS!BE8+BS!BE9 -> 99206.958 | G24: =BS!BJ8+BS!BJ9 -> 134795.19 | H24: =BS!BK8+BS!BK9 -> 178919.6 | I24: =BS!BL8+BS!BL9 -> 225059.43 | J24: =BS!BM8+BS!BM9 -> 277519.38
B25: Inventories | C25: =BS!AP10 -> 32640 | D25: =BS!AU10 -> 34405 | E25: =BS!AZ10 -> 33318 | F25: =BS!BE10 -> 37041.678 | G25: =BS!BJ10 -> 40252.571 | H25: =BS!BK10 -> 41057.622 | I25: =BS!BL10 -> 41878.774 | J25: =BS!BM10 -> 42716.35
B26: Accounts Receivable, Net, & Other | C26: =BS!AP11 -> 32891 | D26: =BS!AU11 -> 42360 | E26: =BS!AZ11 -> 52253 | F26: =BS!BE11 -> 62142.801 | G26: =BS!BJ11 -> 73904.421 | H26: =BS!BK11 -> 87892.135 | I26: =BS!BL11 -> 104527.27 | J26: =BS!BM11 -> 124310.9
B27: PP&E | C27: =BS!AP14 -> 160281 | D27: =BS!AU14 -> 186715 | E27: =BS!AZ14 -> 204177 | F27: =BS!BE14 -> 239987.74 | G27: =BS!BJ14 -> 260543.15 | H27: =BS!BK14 -> 269876.33 | I27: =BS!BL14 -> 275866.86 | J27: =BS!BM14 -> 277808.54
B28: Operating Leases | C28: =BS!AP15 -> 56082 | D28: =BS!AU15 -> 66123 | E28: =BS!AZ15 -> 72513 | F28: =BS!BE15 -> 78425.088 | G28: =BS!BJ15 -> 84819.196 | H28: =BS!BK15 -> 91734.625 | I28: =BS!BL15 -> 99213.879 | J28: =BS!BM15 -> 107302.93
B29: Goodwill | C29: =BS!AP16 -> 15371 | D29: =BS!AU16 -> 20288 | E29: =BS!AZ16 -> 22789 | F29: =BS!BE16 -> 22910 | G29: =BS!BJ16 -> 22943.778 | H29: =BS!BK16 -> 22940.963 | I29: =BS!BL16 -> 22942.84 | J29: =BS!BM16 -> 22942.527
B30: Other Assets | C30: =BS!AP17 -> 27235 | D30: =BS!AU17 -> 42758 | E30: =BS!AZ17 -> 56024 | F30: =BS!BE17 -> 74101.152 | G30: =BS!BJ17 -> 80026.035 | H30: =BS!BK17 -> 86424.652 | I30: =BS!BL17 -> 93334.882 | J30: =BS!BM17 -> 100797.63
B31: Total Assets | C31: =SUM(C24:C30) -> 420549 | D31: =SUM(D24:D30) -> 462675 | E31: =SUM(E24:E30) -> 527854 | F31: =SUM(F24:F30) -> 613815.42 | G31: =SUM(G24:G30) -> 697284.35 | H31: =SUM(H24:H30) -> 778845.93 | I31: =SUM(I24:I30) -> 862823.93 | J31: =SUM(J24:J30) -> 953398.25
B33: Accounts Payable | C33: =BS!AP22 -> 78664 | D33: =BS!AU22 -> 79600 | E33: =BS!AZ22 -> 84981 | F33: =BS!BE22 -> 87415.634 | G33: =BS!BJ22 -> 89850.267 | H33: =BS!BK22 -> 92284.901 | I33: =BS!BL22 -> 94719.535 | J33: =BS!BM22 -> 97154.168
B34: Accrued Expenses & Other | C34: =BS!AP23 -> 51775 | D34: =BS!AU23 -> 62566 | E34: =BS!AZ23 -> 64709 | F34: =BS!BE23 -> 66499 | G34: =BS!BJ23 -> 68289 | H34: =BS!BK23 -> 70079 | I34: =BS!BL23 -> 71869 | J34: =BS!BM23 -> 73659
B35: Unearned Revenue | C35: =BS!AP24 -> 11827 | D35: =BS!AU24 -> 13227 | E35: =BS!AZ24 -> 15227 | F35: =BS!BE24 -> 17134 | G35: =BS!BJ24 -> 19041 | H35: =BS!BK24 -> 20948 | I35: =BS!BL24 -> 22855 | J35: =BS!BM24 -> 24762
B36: Long-Term Lease Liabilities | C36: =BS!AP27 -> 67651 | D36: =BS!AU27 -> 72968 | E36: =BS!AZ27 -> 77297 | F36: =BS!BE27 -> 81208 | G36: =BS!BJ27 -> 85119 | H36: =BS!BK27 -> 89030 | I36: =BS!BL27 -> 92941 | J36: =BS!BM27 -> 96852
B37: Long-Term Debt | C37: =BS!AP28 -> 48744 | D37: =BS!AU28 -> 67150 | E37: =BS!AZ28 -> 58314 | F37: =BS!BE28 -> 56954.6 | G37: =BS!BJ28 -> 66019.33 | H37: =BS!BK28 -> 68502.542 | I37: =BS!BL28 -> 71079.157 | J37: =BS!BM28 -> 73752.686
B38: Other Long-Term Liabilities | C38: =BS!AP29 -> 23643 | D38: =BS!AU29 -> 21121 | E38: =BS!AZ29 -> 25451 | F38: =BS!BE29 -> 33050 | G38: =BS!BJ29 -> 40649 | H38: =BS!BK29 -> 48248 | I38: =BS!BL29 -> 55847 | J38: =BS!BM29 -> 63446
B39: Total Liabilities | C39: =SUM(C33:C38) -> 282304 | D39: =SUM(D33:D38) -> 316632 | E39: =SUM(E33:E38) -> 325979 | F39: =SUM(F33:F38) -> 342261.23 | G39: =SUM(G33:G38) -> 368967.6 | H39: =SUM(H33:H38) -> 389092.44 | I39: =SUM(I33:I38) -> 409310.69 | J39: =SUM(J33:J38) -> 429625.85
B41: Shareholder's Equity | C41: =BS!AP40 -> 138245 | D41: =BS!AU40 -> 146043 | E41: =BS!AZ40 -> 201875 | F41: =BS!BE40 -> 271554.19 | G41: =BS!BJ40 -> 328316.75 | H41: =BS!BK40 -> 389753.49 | I41: =BS!BL40 -> 453513.24 | J41: =BS!BM40 -> 523772.4
B42: Total Equity | C42: =C41 -> 138245 | D42: =D41 -> 146043 | E42: =E41 -> 201875 | F42: =F41 -> 271554.19 | G42: =G41 -> 328316.75 | H42: =H41 -> 389753.49 | I42: =I41 -> 453513.24 | J42: =J41 -> 523772.4
F44: Forecast
B45: Statement of Cash Flows | C45: 2021 | D45: 2022 | E45: 2023 | F45: 2024E | G45: 2025E | H45: 2026E | I45: 2027E | J45: 2028E
B47: Cash Flow from Operations (CFO) | C47: =CF!AP20 -> 46327 | D47: =CF!AU20 -> 46752 | E47: =CF!AZ20 -> 84946 | F47: =CF!BE20 -> 101506.73 | G47: =CF!BJ20 -> 121557.9 | H47: =CF!BK20 -> 142658.14 | I47: =CF!BL20 -> 151772.96 | J47: =CF!BM20 -> 165747.83
B48: Cash Flow from Investing | C48: =CF!AP27 -> -58154 | D48: =CF!AU27 -> -37601 | E48: =CF!AZ27 -> -49833 | F48: =CF!BE27 -> -71440.031 | G48: =CF!BJ27 -> -81398.931 | H48: =CF!BK27 -> -88985.561 | I48: =CF!BL27 -> -97419.158 | J48: =CF!BM27 -> -106806.23
B49: Cash Flow from Financing | C49: =CF!AP36 -> 6291 | D49: =CF!AU36 -> 9718 | E49: =CF!AZ36 -> -15879 | F49: =CF!BE36 -> -11987.286 | G49: =CF!BJ36 -> -13186.014 | H49: =CF!BK36 -> -14504.616 | I49: =CF!BL36 -> -15955.077 | J49: =CF!BM36 -> -17550.585
B50: Foreign Exchange Impact | C50: =CF!AP38 -> -364 | D50: =CF!AU38 -> -1093 | E50: =CF!AZ38 -> 403 | F50: =CF!BE38 -> -68 | G50: =CF!BJ38 -> 0 | H50: =CF!BK38 -> 0 | I50: =CF!BL38 -> 0 | J50: =CF!BM38 -> 0
B52: Cash Balance, Beginning of Period | C52: =CF!AP40 -> 42377 | D52: =C54 -> 36477 | E52: =D54 -> 54253 | F52: =E54 -> 73890 | G52: =F54 -> 91901.414 | H52: =G54 -> 118874.37 | I52: =H54 -> 158042.34 | J52: =I54 -> 196441.06
...

Sheet IS
A1: Amazon.com Inc. (AMZN)
A2: Income Statement
A3: In millions except per share data
BD5: Estimates | BE5: Estimates | BF5: Estimates | BG5: Estimates | BH5: Estimates | BI5: Estimates | BJ5: Estimates | BK5: Estimates | BL5: Estimates | BM5: Estimates
E6: 2008 | F6: 2009 | G6: 2010 | H6: 2011 | I6: 2012 | J6: 2013 | K6: 2014 | L6: 2015 | M6: 42460 | N6: 42551 | O6: 42643 | P6: 42735 | Q6: 2016 | R6: 42825 | S6: 42916 | T6: 43008 | U6: 43100 | V6: 2017 | W6: 43190 | X6: 43281 | Y6: 43373 | Z6: 43465 | AA6: 2018 | AB6: 43555 | AC6: 43646 | AD6: 43738 | AE6: 43830 | AF6: 2019 | AG6: 43921 | AH6: 44012 | AI6: 44104 | AJ6: 44196 | AK6: 2020 | AL6: 44286 | AM6: 44377 | AN6: 44469 | AO6: 44561 | AP6: 2021 | AQ6: 44651 | AR6: 44742 | AS6: 44834 | AT6: 44926 | AU6: 2022 | AV6: 45016 | AW6: 45107 | AX6: 45199 | AY6: 45291 | AZ6: 2023 | BA6: 45382 | BB6: 45473 | BC6: 45565 | BD6: 45657 | BE6: 2024 | BF6: 45747 | BG6: 45838 | BH6: 45930 | BI6: 46022 | BJ6: 2025 | BK6: 2026 | BL6: 2027 | BM6: 2028
A8: Online Stores | K8: 68513 | L8: 76863 | M8: 19916 | N8: 20378 | O8: 21590 | P8: 29548 | Q8: =SUM(M8:P8) -> 91432 | R8: 22826 | S8: 23754 | T8: 26392 | U8: 35383 | V8: =SUM(R8:U8) -> 108355 | W8: 26939 | X8: 27165 | Y8: 29061 | Z8: 39822 | AA8: =SUM(W8:Z8) -> 122987 | AB8: 29498 | AC8: 31053 | AD8: 35039 | AE8: 45657 | AF8: =SUM(AB8:AE8) -> 141247 | AG8: 36652 | AH8: 45896 | AI8: 48350 | AJ8: 66451 | AK8: =SUM(AG8:AJ8) -> 197349 | AL8: 52901 | AM8: 53157 | AN8: 49942 | AO8: 66075 | AP8: =SUM(AL8:AO8) -> 222075 | AQ8: 51129 | AR8: 50855 | AS8: 53489 | AT8: 64531 | AU8: =SUM(AQ8:AT8) -> 220004 | AV8: 51096 | AW8: 52966 | AX8: 57267 | AY8: 70543 | AZ8: =SUM(AV8:AY8) -> 231872 | BA8: 54670 | BB8: 55392 | BC8: 61411 | BD8: =AY8*(1+'Assumptions + Estimates'!J11) -> 74112.673 | BE8: =SUM(BA8:BD8) -> 245585.67 | BF8: =BA8*(1+'Assumptions + Estimates'!K11) -> 57403.5 | BG8: =BB8*(1+'Assumptions + Estimates'!L11) -> 58161.6 | BH8: =BC8*(1+'Assumptions + Estimates'!M11) -> 64481.55 | BI8: =BD8*(1+'Assumptions + Estimates'!N11) -> 77818.306 | BJ8: =SUM(BF8:BI8) -> 257864.96 | BK8: =BJ8*(1+'Assumptions + Estimates'!P11) -> 270758.2 | BL8: =BK8*(1+'Assumptions + Estimates'!Q11) -> 284296.11 | BM8: =BL8*(1+'Assumptions + Estimates'!R11) -> 298510.92
A9: Physical Stores | K9: 0 | L9: 0 | M9: 0 | N9: 0 | O9: 0 | P9: 0 | Q9: =SUM(M9:P9) -> 0 | R9: 0 | S9: 0 | T9: 1276 | U9: 4522 | V9: =SUM(R9:U9) -> 5798 | W9: 4263 | X9: 4312 | Y9: 4248 | Z9: 4401 | AA9: =SUM(W9:Z9) -> 17224 | AB9: 4307 | AC9: 4330 | AD9: 4192 | AE9: 4363 | AF9: =SUM(AB9:AE9) -> 17192 | AG9: 4640 | AH9: 3774 | AI9: 3788 | AJ9: 4022 | AK9: =SUM(AG9:AJ9) -> 16224 | AL9: 3920 | AM9: 4198 | AN9: 4269 | AO9: 4688 | AP9: =SUM(AL9:AO9) -> 17075 | AQ9: 4591 | AR9: 4721 | AS9: 4694 | AT9: 4957 | AU9: =SUM(AQ9:AT9) -> 18963 | AV9: 4895 | AW9: 5024 | AX9: 4959 | AY9: 5152 | AZ9: =SUM(AV9:AY9) -> 20030 | BA9: 5202 | BB9: 5206 | BC9: 5228 | BD9: =AY9*(1+'Assumptions + Estimates'!J12) -> 5410.0939 | BE9: =SUM(BA9:BD9) -> 21046.094 | BF9: =BA9*(1+'Assumptions + Estimates'!K12) -> 5462.1 | BG9: =BB9*(1+'Assumptions + Estimates'!L12) -> 5466.3 | BH9: =BC9*(1+'Assumptions + Estimates'!M12) -> 5489.4 | BI9: =BD9*(1+'Assumptions + Estimates'!N12) -> 5680.5985 | BJ9: =SUM(BF9:BI9) -> 22098.399 | BK9: =BJ9*(1+'Assumptions + Estimates'!P12) -> 23203.318 | BL9: =BK9*(1+'Assumptions + Estimates'!Q12) -> 24363.484 | BM9: =BL9*(1+'Assumptions + Estimates'!R12) -> 25581.659
A10: Third-Party Seller Services | K10: 11747 | L10: 16086 | M10: 4801 | N10: 5083 | O10: 5652 | P10: 7456 | Q10: =SUM(M10:P10) -> 22992 | R10: 6438 | S10: 6991 | T10: 7928 | U10: 10523 | V10: =SUM(R10:U10) -> 31880 | W10: 9265 | X10: 9702 | Y10: 10395 | Z10: 13383 | AA10: =SUM(W10:Z10) -> 42745 | AB10: 11141 | AC10: 11962 | AD10: 13212 | AE10: 17446 | AF10: =SUM(AB10:AE10) -> 53761 | AG10: 14479 | AH10: 18195 | AI10: 20436 | AJ10: 27327 | AK10: =SUM(AG10:AJ10) -> 80437 | AL10: 23709 | AM10: 25085 | AN10: 24252 | AO10: 30320 | AP10: =SUM(AL10:AO10) -> 103366 | AQ10: 25335 | AR10: 27376 | AS10: 28666 | AT10: 36339 | AU10: =SUM(AQ10:AT10) -> 117716 | AV10: 29820 | AW10: 32332 | AX10: 34342 | AY10: 43559 | AZ10: =SUM(AV10:AY10) -> 140053 | BA10: 34596 | BB10: 36201 | BC10: 37864 | BD10: =AY10*(1+'Assumptions + Estimates'!J13) -> 49126.331 | BE10: =SUM(BA10:BD10) -> 157787.33 | BF10: =BA10*(1+'Assumptions + Estimates'!K13) -> 38055.6 | BG10: =BB10*(1+'Assumptions + Estimates'!L13) -> 39821.1 | BH10: =BC10*(1+'Assumptions + Estimates'!M13) -> 41650.4 | BI10: =BD10*(1+'Assumptions + Estimates'!N13) -> 54038.964 | BJ10: =SUM(BF10:BI10) -> 173566.06 | BK10: =BJ10*(1+'Assumptions + Estimates'!P13) -> 190922.67 | BL10: =BK10*(1+'Assumptions + Estimates'!Q13) -> 210014.94 | BM10: =BL10*(1+'Assumptions + Estimates'!R13) -> 231016.43
A11: Subscription Services | K11: 2762 | L11: 4467 | M11: 1300 | N11: 1431 | O11: 1532 | P11: 2130 | Q11: =SUM(M11:P11) -> 6393 | R11: 1939 | S11: 2165 | T11: 2441 | U11: 3177 | V11: =SUM(R11:U11) -> 9722 | W11: 3102 | X11: 3408 | Y11: 3698 | Z11: 3959 | AA11: =SUM(W11:Z11) -> 14167 | AB11: 4342 | AC11: 4676 | AD11: 4957 | AE11: 5235 | AF11: =SUM(AB11:AE11) -> 19210 | AG11: 5556 | AH11: 6018 | AI11: 6572 | AJ11: 7061 | AK11: =SUM(AG11:AJ11) -> 25207 | AL11: 7580 | AM11: 7917 | AN11: 8148 | AO11: 8123 | AP11: =SUM(AL11:AO11) -> 31768 | AQ11: 8410 | AR11: 8716 | AS11: 8903 | AT11: 9189 | AU11: =SUM(AQ11:AT11) -> 35218 | AV11: 9657 | AW11: 9894 | AX11: 10170 | AY11: 10488 | AZ11: =SUM(AV11:AY11) -> 40209 | BA11: 10722 | BB11: 10866 | BC11: 11278 | BD11: =AY11*(1+'Assumptions + Estimates'!J14) -> 11697.622 | BE11: =SUM(BA11:BD11) -> 44563.622 | BF11: =BA11*(1+'Assumptions + Estimates'!K14) -> 11794.2 | BG11: =BB11*(1+'Assumptions + Estimates'!L14) -> 11952.6 | BH11: =BC11*(1+'Assumptions + Estimates'!M14) -> 12405.8 | BI11: =BD11*(1+'Assumptions + Estimates'!N14) -> 12867.384 | BJ11: =SUM(BF11:BI11) -> 49019.984 | BK11: =BJ11*(1+'Assumptions + Estimates'!P14) -> 53921.982 | BL11: =BK11*(1+'Assumptions + Estimates'!Q14) -> 59314.181 | BM11: =BL11*(1+'Assumptions + Estimates'!R14) -> 65245.599
A12: Advertising Services | Q12: =SUM(M12:P12) -> 0 | V12: =SUM(R12:U12) -> 0 | AA12: =SUM(W12:Z12) -> 0 | AF12: =SUM(AB12:AE12) -> 0 | AI12: 4982 | AJ12: 7350 | AK12: =SUM(AG12:AJ12) -> 12332 | AL12: 6381 | AM12: 7451 | AN12: 7612 | AO12: 9716 | AP12: =SUM(AL12:AO12) -> 31160 | AQ12: 7877 | AR12: 8757 | AS12: 9548 | AT12: 11557 | AU12: =SUM(AQ12:AT12) -> 37739 | AV12: 9509 | AW12: 10683 | AX12: 12060 | AY12: 14654 | AZ12: =SUM(AV12:AY12) -> 46906 | BA12: 11824 | BB12: 12771 | BC12: 14331 | BD12: =AY12*(1+'Assumptions + Estimates'!J15) -> 17458.636 | BE12: =SUM(BA12:BD12) -> 56384.636 | BF12: =BA12*(1+'Assumptions + Estimates'!K15) -> 13952.32 | BG12: =BB12*(1+'Assumptions + Estimates'!L15) -> 15069.78 | BH12: =BC12*(1+'Assumptions + Estimates'!M15) -> 16910.58 | BI12: =BD12*(1+'Assumptions + Estimates'!N15) -> 20601.19 | BJ12: =SUM(BF12:BI12) -> 66533.87 | BK12: =BJ12*(1+'Assumptions + Estimates'!P15) -> 76513.95 | BL12: =BK12*(1+'Assumptions + Estimates'!Q15) -> 87991.043 | BM12: =BL12*(1+'Assumptions + Estimates'!R15) -> 101189.7
A13: AWS | K13: 4644 | L13: 7880 | M13: 2566 | N13: 2886 | O13: 3231 | P13: 3536 | Q13: =SUM(M13:P13) -> 12219 | R13: 3661 | S13: 4100 | T13: 4584 | U13: 5113 | V13: =SUM(R13:U13) -> 17458 | W13: 5442 | X13: 6105 | Y13: 6679 | Z13: 7430 | AA13: =SUM(W13:Z13) -> 25656 | AB13: 7696 | AC13: 8381 | AD13: 8995 | AE13: 9954 | AF13: =SUM(AB13:AE13) -> 35026 | AG13: 10219 | AH13: 10808 | AI13: 11601 | AJ13: 12742 | AK13: =SUM(AG13:AJ13) -> 45370 | AL13: 13503 | AM13: 14809 | AN13: 16110 | AO13: 17780 | AP13: =SUM(AL13:AO13) -> 62202 | AQ13: 18441 | AR13: 19739 | AS13: 20538 | AT13: 21378 | AU13: =SUM(AQ13:AT13) -> 80096 | AV13: 21354 | AW13: 22140 | AX13: 23059 | AY13: 24204 | AZ13: =SUM(AV13:AY13) -> 90757 | BA13: 25037 | BB13: 26281 | BC13: 27452 | BD13: =AY13*(1+'Assumptions + Estimates'!J16) -> 28641.964 | BE13: =SUM(BA13:BD13) -> 107411.96 | BF13: =BA13*(1+'Assumptions + Estimates'!K16) -> 29543.66 | BG13: =BB13*(1+'Assumptions + Estimates'!L16) -> 31011.58 | BH13: =BC13*(1+'Assumptions + Estimates'!M16) -> 32393.36 | BI13: =BD13*(1+'Assumptions + Estimates'!N16) -> 33797.518 | BJ13: =SUM(BF13:BI13) -> 126746.12 | BK13: =BJ13*(1+'Assumptions + Estimates'!P16) -> 145758.04 | BL13: =BK13*(1+'Assumptions + Estimates'!Q16) -> 167621.74 | BM13: =BL13*(1+'Assumptions + Estimates'!R16) -> 192765
A14: Other | K14: 1322 | L14: 1710 | M14: 545 | N14: 626 | O14: 709 | P14: 1071 | Q14: =SUM(M14:P14) -> 2951 | R14: 850 | S14: 945 | T14: 1123 | U14: 1735 | V14: =SUM(R14:U14) -> 4653 | W14: 2031 | X14: 2194 | Y14: 2495 | Z14: 3388 | AA14: =SUM(W14:Z14) -> 10108 | AB14: 2716 | AC14: 3002 | AD14: 3586 | AE14: 4782 | AF14: =SUM(AB14:AE14) -> 14086 | AG14: 3906 | AH14: 4221 | AI14: 416 | AJ14: 602 | AK14: =SUM(AG14:AJ14) -> 9145 | AL14: 524 | AM14: 463 | AN14: 479 | AO14: 710 | AP14: =SUM(AL14:AO14) -> 2176 | AQ14: 661 | AR14: 1070 | AS14: 1263 | AT14: 1253 | AU14: =SUM(AQ14:AT14) -> 4247 | AV14: 1027 | AW14: 1344 | AX14: 1226 | AY14: 1361 | AZ14: =SUM(AV14:AY14) -> 4958 | BA14: 1262 | BB14: 1260 | BC14: 1313 | BD14: =AY14*(1+'Assumptions + Estimates'!J17) -> 1429.05 | BE14: =SUM(BA14:BD14) -> 5264.05 | BF14: =BA14*(1+'Assumptions + Estimates'!K17) -> 1325.1 | BG14: =BB14*(1+'Assumptions + Estimates'!L17) -> 1323 | BH14: =BC14*(1+'Assumptions + Estimates'!M17) -> 1378.65 | BI14: =BD14*(1+'Assumptions + Estimates'!N17) -> 1500.5025 | BJ14: =SUM(BF14:BI14) -> 5527.2525 | BK14: =BJ14*(1+'Assumptions + Estimates'!P17) -> 5803.6151 | BL14: =BK14*(1+'Assumptions + Estimates'!Q17) -> 6093.7959 | BM14: =BL14*(1+'Assumptions + Estimates'!R17) -> 6398.4857
A15: Total Revenue | E15: 19166 | F15: 24509 | G15: 34204 | H15: 48077 | I15: 61093 | J15: 74452 | K15: =SUM(K8:K14) -> 88988 | L15: =SUM(L8:L14) -> 107006 | M15: =SUM(M8:M14) -> 29128 | N15: =SUM(N8:N14) -> 30404 | O15: =SUM(O8:O14) -> 32714 | P15: =SUM(P8:P14) -> 43741 | Q15: =SUM(Q8:Q14) -> 135987 | R15: =SUM(R8:R14) -> 35714 | ... BM15: =SUM(BM8:BM14) -> 920707.8
A16: Total Cost of Goods Sold | E16: 14896 | F16: 18978 | G16: 26561 | H16: 37288 | I16: 45971 | J16: 54181 | K16: 62752 | L16: 71651 | M16: 18866 | N16: 19180 | O16: 21260 | P16: 28958 | Q16: 88264 | R16: 22440 | S16: 23451 | T16: 27549 | U16: 38494 | V16: 111934 | W16: 30735 | X16: 30632 | Y16: 33003 | Z16: 44786 | AA16: 139156 | AB16: 33920 | AC16: 36337 | AD16: 41302 | AE16: 53977 | AF16: 165536 | AG16: 44257 | AH16: 52660 | AI16: 57106 | AJ16: 79284 | AK16: 233307 | AL16: 62403 | AM16: 64176 | AN16: 62930 | AO16: 82835 | AP16: 272344 | AQ16: 66499 | AR16: 66424 | AS16: 70268 | AT16: 85640 | AU16: 288831 | AV16: 67791 | AW16: 69373 | AX16: 75022 | AY16: 92553 | AZ16: 304739 | BA16: 72633 | BB16: 73785 | BC16: 80977 | BD16: =BD$15*'Assumptions + Estimates'!J23 -> 99574.475 | BE16: =SUM(BA16:BD16) -> 326969.48 | BF16: =BF$15*'Assumptions + Estimates'!$O23 -> 81918.97 | BG16: =BG$15*'Assumptions + Estimates'!$O23 -> 84659.099 | BH16: =BH$15*'Assumptions + Estimates'!$O23 -> 90849.065 | BI16: =BI$15*'Assumptions + Estimates'!$O23 -> 107278.32 | BJ16: =SUM(BF16:BI16) -> 364705.45 | BK16: =BK$15*'Assumptions + Estimates'!P23 -> 391109.71 | BL16: =BL$15*'Assumptions + Estimates'!Q23 -> 419847.65 | BM16: =BM$15*'Assumptions + Estimates'!R23 -> 451146.82
A17: Gross Profit (GAAP) | E17: =E15-E16 -> 4270 | F17: =F15-F16 -> 5531 | G17: =G15-G16 -> 7643 | H17: =H15-H16 -> 10789 | I17: =I15-I16 -> 15122 | J17: =J15-J16 -> 20271 | K17: =K15-K16 -> 26236 | L17: =L15-L16 -> 35355 | ... BM17: =BM15-BM16 -> 469560.98
A18: Fulfillment | E18: 1658 | F18: 2052 | G18: 2898 | H18: 4576 | I18: 6419 | J18: 8585 | K18: 10766 | L18: 13410 | M18: 3687 | N18: 3878 | O18: 4335 | P18: 5719 | Q18: 17619 | R18: 4697 | S18: 5158 | T18: 6420 | U18: 8974 | V18: 25249 | W18: 7792 | X18: 7932 | Y18: 8275 | Z18: 10028 | AA18: 34027 | AB18: 8601 | AC18: 9271 | AD18: 10167 | AE18: 12192 | AF18: 40231 | AG18: 11531 | AH18: 13806 | AI18: 14705 | AJ18: 18474 | AK18: 58516 | AL18: 16530 | AM18: 17638 | AN18: 18498 | AO18: 22445 | AP18: 75111 | AQ18: 20271 | AR18: 20342 | AS18: 20583 | AT18: 23103 | AU18: 84299 | AV18: 20905 | AW18: 21305 | AX18: 22314 | AY18: 26095 | AZ18: 90619 | BA18: 22317 | BB18: 23566 | BC18: 24660 | BD18: =BD$15*'Assumptions + Estimates'!J25 -> 28932.961 | BE18: =SUM(BA18:BD18) -> 99475.961 | BF18: =BF$15*'Assumptions + Estimates'!$O25 -> 24260.618 | BG18: =BG$15*'Assumptions + Estimates'!$O25 -> 25072.118 | BH18: =BH$15*'Assumptions + Estimates'!$O25 -> 26905.3 | BI18: =BI$15*'Assumptions + Estimates'!$O25 -> 31770.887 | BJ18: =SUM(BF18:BI18) -> 108008.92 | BK18: =BK$15*'Assumptions + Estimates'!P25 -> 115032.27 | BL18: =BL$15*'Assumptions + Estimates'!Q25 -> 125954.29 | BM18: =BM$15*'Assumptions + Estimates'!R25 -> 138106.17
A19: Technology and Content | E19: 482 | F19: 680 | G19: 1029 | H19: 1630 | I19: 2408 | J19: 3133 | K19: 4332 | L19: 5254 | M19: 1436 | N19: 1546 | O19: 1738 | P19: 2513 | Q19: 7233 | R19: 1920 | S19: 2229 | T19: 2479 | U19: 3440 | V19: 10068 | W19: 2699 | X19: 2901 | Y19: 3303 | Z19: 7669 | AA19: 16572 | AB19: 7927 | AC19: 9065 | AD19: 9200 | AE19: 9740 | AF19: 35932 | AG19: 9325 | AH19: 10388 | AI19: 10976 | AJ19: 12049 | AK19: 42738 | AL19: 12488 | AM19: 13871 | AN19: 14380 | AO19: 15313 | AP19: 56052 | AQ19: 14842 | AR19: 18072 | AS19: 19485 | AT19: 20814 | AU19: 73213 | AV19: 20450 | AW19: 21931 | AX19: 21203 | AY19: 22038 | AZ19: 85622 | BA19: 20424 | BB19: 22304 | BC19: 22245 | BD19: =BD$15*'Assumptions + Estimates'!J26 -> 24423.928 | BE19: =SUM(BA19:BD19) -> 89396.928 | BF19: =BF$15*'Assumptions + Estimates'!$O26 -> 20479.742 | BG19: =BG$15*'Assumptions + Estimates'!$O26 -> 21164.775 | BH19: =BH$15*'Assumptions + Estimates'!$O26 -> 22712.266 | BI19: =BI$15*'Assumptions + Estimates'!$O26 -> 26819.58 | BJ19: =SUM(BF19:BI19) -> 91176.364 | BK19: =BK$15*'Assumptions + Estimates'!P26 -> 99694.631 | BL19: =BL$15*'Assumptions + Estimates'!Q26 -> 117557.34 | BM19: =BM$15*'Assumptions + Estimates'!R26 -> 138106.17
A20: Marketing | E20: 1033 | F20: 1240 | G20: 1734 | H20: 2909 | I20: 4564 | J20: 6565 | K20: 9275 | L20: 12540 | M20: 3526 | N20: 3880 | O20: 4135 | P20: 4545 | Q20: 16086 | R20: 4813 | S20: 5549 | T20: 5944 | U20: 6314 | V20: 22620 | W20: 6759 | X20: 7247 | Y20: 7162 | Z20: 4911 | AA20: 26079 | AB20: 3664 | AC20: 4291 | AD20: 4752 | AE20: 6172 | AF20: 18879 | AG20: 4828 | AH20: 4345 | AI20: 5434 | AJ20: 7403 | AK20: 22010 | AL20: 6207 | AM20: 7524 | AN20: 8010 | AO20: 10810 | AP20: 32551 | AQ20: 8320 | AR20: 10086 | AS20: 11014 | AT20: 12818 | AU20: 42238 | AV20: 10172 | AW20: 10745 | AX20: 10551 | AY20: 12902 | AZ20: 44370 | BA20: 9662 | BB20: 10512 | BC20: 10609 | BD20: =BD$15*'Assumptions + Estimates'!J27 -> 13151.346 | BE20: =SUM(BA20:BD20) -> 43934.346 | BF20: =BF$15*'Assumptions + Estimates'!$O27 -> 11027.554 | BG20: =BG$15*'Assumptions + Estimates'!$O27 -> 11396.417 | BH20: =BH$15*'Assumptions + Estimates'!$O27 -> 12229.682 | BI20: =BI$15*'Assumptions + Estimates'!$O27 -> 14441.312 | BJ20: =SUM(BF20:BI20) -> 49094.965 | BK20: =BK$15*'Assumptions + Estimates'!P27 -> 61350.542 | BL20: =BL$15*'Assumptions + Estimates'!Q27 -> 67175.624 | BM20: =BM$15*'Assumptions + Estimates'!R27 -> 73656.624
A21: General & Administrative | E21: 279 | F21: 328 | G21: 470 | H21: 658 | I21: 896 | J21: 1129 | K21: 1552 | L21: 1747 | M21: 497 | N21: 580 | O21: 639 | P21: 717 | Q21: 2433 | R21: 795 | S21: 874 | T21: 960 | U21: 1044 | V21: 3673 | W21: 1067 | X21: 1111 | Y21: 1041 | Z21: 1117 | AA21: 4336 | AB21: 1173 | AC21: 1270 | AD21: 1348 | AE21: 1412 | AF21: 5203 | AG21: 1452 | AH21: 1580 | AI21: 1668 | AJ21: 1968 | AK21: 6668 | AL21: 1987 | AM21: 2158 | AN21: 2153 | AO21: 2525 | AP21: 8823 | AQ21: 2594 | AR21: 2903 | AS21: 3061 | AT21: 3333 | AU21: 11891 | AV21: 3043 | AW21: 3202 | AX21: 2561 | AY21: 3010 | AZ21: 11816 | BA21: 2742 | BB21: 3041 | BC21: 2713 | BD21: =BD$15*'Assumptions + Estimates'!J28 -> 3757.5274 | BE21: =SUM(BA21:BD21) -> 12253.527 | BF21: =BF$15*'Assumptions + Estimates'!$O28 -> 3150.7296 | BG21: =BG$15*'Assumptions + Estimates'!$O28 -> 3256.1192 | BH21: =BH$15*'Assumptions + Estimates'!$O28 -> 3494.1948 | BI21: =BI$15*'Assumptions + Estimates'!$O28 -> 4126.0893 | BJ21: =SUM(BF21:BI21) -> 14027.133 | BK21: =BK$15*'Assumptions + Estimates'!P28 -> 19172.044 | BL21: =BL$15*'Assumptions + Estimates'!Q28 -> 25190.859 | BM21: =BM$15*'Assumptions + Estimates'!R28 -> 27621.234
A22: Other Operating Expenses (Income) | E22: -24 | F22: 102 | G22: 106 | H22: 154 | I22: 159 | J22: 114 | K22: 133 | L22: 171 | M22: 45 | N22: 55 | O22: 32 | P22: 34 | Q22: 166 | R22: 44 | S22: 66 | T22: 45 | U22: 60 | V22: 215 | W22: 63 | X22: 80 | Y22: 68 | Z22: 86 | AA22: 297 | AB22: -5 | AC22: 86 | AD22: 55 | AE22: 65 | AF22: 201 | AG22: 70 | AH22: 290 | AI22: 62 | AJ22: -496 | AK22: -74 | AL22: 38 | AM22: 11 | AN22: -11 | AO22: 24 | AP22: 62 | AQ22: 249 | AR22: 90 | AS22: 165 | AT22: 759 | AU22: 1263 | AV22: 223 | AW22: 146 | AX22: 244 | AY22: 154 | AZ22: 767 | BA22: 228 | BB22: 97 | BC22: 262 | BD22: =BD$15*'Assumptions + Estimates'!J29 -> 187.87637 | BE22: =SUM(BA22:BD22) -> 774.87637 | BF22: =BF$15*'Assumptions + Estimates'!$O29 -> 157.53648 | BG22: =BG$15*'Assumptions + Estimates'!$O29 -> 162.80596 | BH22: =BH$15*'Assumptions + Estimates'!$O29 -> 174.70974 | BI22: =BI$15*'Assumptions + Estimates'!$O29 -> 206.30446 | BJ22: =SUM(BF22:BI22) -> 701.35664 | BK22: =BK$15*'Assumptions + Estimates'!P29 -> 766.88178 | BL22: =BL$15*'Assumptions + Estimates'!Q29 -> 839.6953 | BM22: =BM$15*'Assumptions + Estimates'!R29 -> 920.7078
A23: Total Operating Expenses | E23: =SUM(E18:E22) -> 3428 | F23: =SUM(F18:F22) -> 4402 | G23: =SUM(G18:G22) -> 6237 | H23: =SUM(H18:H22) -> 9927 | I23: =SUM(I18:I22) -> 14446 | J23: =SUM(J18:J22) -> 19526 | K23: =SUM(K18:K22) -> 26058 | L23: =SUM(L18:L22) -> 33122 | ... BM23: =SUM(BM18:BM22) -> 378410.9
A24: Operating Profit (GAAP) | E24: =E17-E23 -> 842 | F24: =F17-F23 -> 1129 | G24: =G17-G23 -> 1406 | H24: =H17-H23 -> 862 | I24: =I17-I23 -> 676 | J24: =J17-J23 -> 745 | K24: =K17-K23 -> 178 | L24: =L17-L23 -> 2233 | ... BM24: =BM17-BM23 -> 91150.072
A25: Interest Income | E25: 83 | F25: 37 | G25: 51 | H25: 61 | I25: 40 | J25: 38 | K25: 39 | L25: 50 | M25: 21 | N25: 24 | O25: 26 | P25: 30 | Q25: 101 | R25: 39 | S25: 44 | T25: 54 | U25: 66 | V25: 203 | W25: 80 | X25: 94 | Y25: 117 | Z25: 150 | AA25: 441 | AB25: 183 | AC25: 215 | AD25: 224 | AE25: 211 | AF25: 833 | AG25: 202 | AH25: 135 | AI25: 118 | AJ25: 100 | AK25: 555 | AL25: 105 | AM25: 106 | AN25: 119 | AO25: 118 | AP25: 448 | AQ25: 108 | AR25: 159 | AS25: 277 | AT25: 445 | AU25: 989 | AV25: 611 | AW25: 661 | AX25: 776 | AY25: 901 | AZ25: 2949 | BA25: 993 | BB25: 1180 | BC25: 1256 | BD25: =BD$15*'Assumptions + Estimates'!J32 -> 939.38184 | BE25: =SUM(BA25:BD25) -> 4368.3818 | BF25: =BF$15*'Assumptions + Estimates'!$O32 -> 787.6824 | BG25: =BG$15*'Assumptions + Estimates'!$O32 -> 814.0298 | BH25: =BH$15*'Assumptions + Estimates'!$O32 -> 873.5487 | BI25: =BI$15*'Assumptions + Estimates'!$O32 -> 1031.5223 | BJ25: =SUM(BF25:BI25) -> 3506.7832 | BK25: =BK$15*'Assumptions + Estimates'!P32 -> 3834.4089 | BL25: =BL$15*'Assumptions + Estimates'!Q32 -> 4198.4765 | BM25: =BM$15*'Assumptions + Estimates'!R32 -> 4603.539
A26: Interest Expense | E26: -71 | F26: -34 | G26: -39 | H26: -65 | I26: -92 | J26: -141 | K26: -210 | L26: -459 | M26: -117 | N26: -116 | O26: -118 | P26: -133 | Q26: -484 | R26: -139 | S26: -143 | T26: -228 | U26: -339 | V26: -849 | W26: -330 | X26: -343 | Y26: -358 | Z26: -387 | AA26: -1418 | AB26: -366 | AC26: -383 | AD26: -396 | AE26: -455 | AF26: -1600 | AG26: -402 | AH26: -403 | AI26: -428 | AJ26: -414 | AK26: -1647 | AL26: -399 | AM26: -435 | AN26: -493 | AO26: -482 | AP26: -1809 | AQ26: -472 | AR26: -584 | AS26: -617 | AT26: -694 | AU26: -2367 | AV26: -823 | AW26: -840 | AX26: -806 | AY26: -713 | AZ26: -3182 | BA26: -644 | BB26: -589 | BC26: -603 | BD26: =BD$15*'Assumptions + Estimates'!J33 -> -1878.7637 | BE26: =SUM(BA26:BD26) -> -3714.7637 | BF26: =BF$15*'Assumptions + Estimates'!$O33 -> -1575.3648 | BG26: =BG$15*'Assumptions + Estimates'!$O33 -> -1628.0596 | BH26: =BH$15*'Assumptions + Estimates'!$O33 -> -1747.0974 | BI26: =BI$15*'Assumptions + Estimates'!$O33 -> -2063.0446 | BJ26: =SUM(BF26:BI26) -> -7013.5664 | BK26: =BK$15*'Assumptions + Estimates'!P33 -> -7668.8178 | BL26: =BL$15*'Assumptions + Estimates'!Q33 -> -8396.953 | BM26: =BM$15*'Assumptions + Estimates'!R33 -> -9207.078
A27: Other Income, Net | E27: 47 | F27: 29 | G27: 79 | H27: 76 | I27: -80 | J27: -136 | K27: -118 | L27: -256 | M27: 81 | N27: -14 | O27: 8 | P27: 14 | Q27: 89 | R27: 48 | S27: 137 | T27: 143 | U27: 18 | V27: 346 | W27: 239 | X27: -129 | Y27: -93 | Z27: -199 | AA27: -182 | AB27: 164 | AC27: -27 | AD27: -353 | AE27: 418 | AF27: 202 | AG27: -406 | AH27: 646 | AI27: 925 | AJ27: 1206 | AK27: 2371 | AL27: 1697 | AM27: 1261 | AN27: -163 | AO27: 11838 | AP27: 14633 | AQ27: -8570 | AR27: -5545 | AS27: 759 | AT27: -3450 | AU27: -16806 | AV27: -443 | AW27: 61 | AX27: 1031 | AY27: 289 | AZ27: 938 | BA27: -2673 | BB27: -18 | BC27: -27 | BD27: =BD$15*'Assumptions + Estimates'!J34 -> 375.75274 | BE27: =SUM(BA27:BD27) -> -2342.2473 | BF27: =BF$15*'Assumptions + Estimates'!$O34 -> 315.07296 | BG27: =BG$15*'Assumptions + Estimates'!$O34 -> 325.61192 | BH27: =BH$15*'Assumptions + Estimates'!$O34 -> 349.41948 | BI27: =BI$15*'Assumptions + Estimates'!$O34 -> 412.60893 | BJ27: =SUM(BF27:BI27) -> 1402.7133 | BK27: =BK$15*'Assumptions + Estimates'!P34 -> 1533.7636 | BL27: =BL$15*'Assumptions + Estimates'!Q34 -> 1679.3906 | BM27: =BM$15*'Assumptions + Estimates'!R34 -> 1841.4156
A28: Pre Tax Income | E28: =E24+E25+E26+E27 -> 901 | F28: =F24+F25+F26+F27 -> 1161 | G28: =G24+G25+G26+G27 -> 1497 | H28: =H24+H25+H26+H27 -> 934 | I28: =I24+I25+I26+I27 -> 544 | J28: =J24+J25+J26+J27 -> 506 | K28: =K24+K25+K26+K27 -> -111 | L28: =L24+L25+L26+L27 -> 1568 | ... BM28: =BM24+BM25+BM26+BM27 -> 88387.948
A29: Income Tax (Provision)/Benefit | E29: -247 | F29: -253 | G29: -352 | H29: -291 | I29: -428 | J29: -161 | K29: -167 | L29: -950 | M29: -475 | N29: -307 | O29: -229 | P29: -414 | Q29: -1425 | R29: -229 | S29: -467 | T29: -58 | U29: -16 | V29: -770 | W29: -287 | X29: -74 | Y29: -508 | Z29: -327 | AA29: -1196 | AB29: -836 | AC29: -257 | AD29: -494 | AE29: -786 | AF29: -2373 | AG29: -744 | AH29: -984 | AI29: -569 | AJ29: -566 | AK29: -2863 | AL29: -2156 | AM29: -868 | AN29: -1155 | AO29: -612 | AP29: -4791 | AQ29: 1422 | AR29: 637 | AS29: -69 | AT29: 1227 | AU29: =SUM(AQ29:AT29) -> 3217 | AV29: -948 | AW29: -804 | AX29: -2306 | AY29: -3062 | AZ29: =SUM(AV29:AY29) -> -7120 | BA29: -2467 | BB29: -1767 | BC29: -2706 | BD29: =IF(BD28>0,BD28*-'Assumptions + Estimates'!J39) -> -3629.7714 | BE29: =SUM(BA29:BD29) -> -10569.771 | BF29: =IF(BF28>0,BF28*-'Assumptions + Estimates'!$O39,0) -> -3374.4314 | BG29: =IF(BG28>0,BG28*-'Assumptions + Estimates'!$O39,0) -> -3487.3037 | BH29: =IF(BH28>0,BH28*-'Assumptions + Estimates'!$O39,0) -> -3742.2826 | BI29: =IF(BI28>0,BI28*-'Assumptions + Estimates'!$O39,0) -> -4419.0416 | BJ29: =SUM(BF29:BI29) -> -15023.059 | BK29: =IF(BK28>0,BK28*-'Assumptions + Estimates'!P39,0) -> -16265.562 | BL29: =IF(BL28>0,BL28*-'Assumptions + Estimates'!Q39,0) -> -16928.257 | BM29: =IF(BM28>0,BM28*-'Assumptions + Estimates'!R39,0) -> -18561.469
A30: Equity Income (Net of Tax) | E30: -9 | F30: -6 | G30: 7 | H30: -12 | I30: -155 | J30: -71 | K30: 37 | L30: -22 | M30: -68 | N30: -15 | O30: -10 | P30: -3 | Q30: -96 | R30: 0 | S30: -2 | T30: -2 | U30: 0 | V30: -4 | W30: 0 | X30: 3 | Y30: 1 | Z30: 4 | AA30: 8 | AB30: -4 | AC30: -7 | AD30: -4 | AE30: 1 | AF30: -14 | AG30: -104 | AH30: 6 | AI30: 91 | AJ30: 23 | AK30: 16 | AL30: -5 | AM30: 12 | AN30: -4 | AO30: 1 | AP30: 4 | AQ30: -1 | AR30: -12 | AS30: -3 | AT30: 13 | AU30: =SUM(AQ30:AT30) -> -3 | AV30: 1 | AW30: -9 | AX30: -4 | AY30: 0 | AZ30: =SUM(AV30:AY30) -> -12 | BA30: -85 | BB30: 7 | BC30: -3 | BD30: 0 | BE30: =SUM(BA30:BD30) -> -81 | BF30: 0 | BG30: 0 | BH30: 0 | BI30: 0 | BJ30: =SUM(BF30:BI30) -> 0 | BK30: 0 | BL30: 0 | BM30: 0
A31: Net Income | E31: =E28+E29+E30 -> 645 | F31: =F28+F29+F30 -> 902 | G31: =G28+G29+G30 -> 1152 | H31: =H28+H29+H30 -> 631 | I31: =I28+I29+I30 -> -39 | J31: =J28+J29+J30 -> 274 | K31: =K28+K29+K30 -> -241 | L31: =L28+L29+L30 -> 596 | ... BM31: =BM28+BM29+BM30 -> 69826.479
A32: EPS Basic | E32: =ROUND(E31/E35,2) -> 0.08 | F32: =ROUND(F31/F35,2) -> 0.1 | G32: =ROUND(G31/G35,2) -> 0.13 | H32: =ROUND(H31/H35,2) -> 0.07 | I32: =ROUND(I31/I35,2) -> 0 | J32: =ROUND(J31/J35,2) -> 0.03 | K32: =ROUND(K31/K35,2) -> -0.03 | L32: =ROUND(L31/L35,2) -> 0.06 | Q32: =ROUND(Q31/Q35,2) -> 0.25 | V32: =ROUND(V31/V35,2) -> 0.32 | AA32: =ROUND(AA31/AA35,2) -> 1.03 | AF32: =ROUND(AF31/AF35,2) -> 1.17 | AK32: =ROUND(AK31/AK35,2) -> 2.13 | AP32: =ROUND(AP31/AP35,2) -> 3.3 | AU32: =ROUND(AU31/AU35,2) -> -0.27 | AZ32: =ROUND(AZ31/AZ35,2) -> 2.95 | BE32: =ROUND(BE31/BE35,2) -> 5.02 | BJ32: =ROUND(BJ31/BJ35,2) -> 5.31 | BK32: =ROUND(BK31/BK35,2) -> 5.68 | BL32: =ROUND(BL31/BL35,2) -> 5.85 | BM32: =ROUND(BM31/BM35,2) -> 6.34
A33: EPS (GAAP) | E33: =ROUND(E31/E36,2) -> 0.07 | F33: =ROUND(F31/F36,2) -> 0.1 | G33: =ROUND(G31/G36,2) -> 0.13 | H33: =ROUND(H31/H36,2) -> 0.07 | I33: =ROUND(I31/I36,2) -> 0 | J33: =ROUND(J31/J36,2) -> 0.03 | K33: =ROUND(K31/K36,2) -> -0.03 | L33: =ROUND(L31/L36,2) -> 0.06 | ... BM33: =ROUND(BM31/BM36,2) -> 6.24
A34: Weighted-average shares used:
A35: Basic Share Count | E35: 8460 | F35: 8660 | G35: 8940 | H35: 9060 | I35: 9060 | J35: 9140 | K35: 9240 | L35: 9340 | Q35: 9480 | V35: 9600 | AA35: 9740 | AF35: 9880 | AK35: 10005 | AP35: 10117 | AU35: 10189 | AX35: 10322 | AZ35: 10304 | BC35: 10501 | BE35: =BE36-(AZ36-AZ35) -> 10530.25 | BJ35: =BJ36-(BE36-BE35) -> 10647 | BK35: =BK36-(BJ36-BJ35) -> 10767 | BL35: =BL36-(BK36-BK35) -> 10887 | BM35: =BM36-(BL36-BL35) -> 11007
A36: Diluted Share Count | E36: 8640 | F36: 8840 | G36: 9120 | H36: 9220 | I36: 9060 | J36: 9300 | K36: 9240 | L36: 9540 | M36: 9620 | N36: 9656 | O36: 9700 | P36: 9720 | Q36: 9680 | R36: 9800 | S36: 9840 | T36: 9880 | U36: 9910 | V36: 9860 | W36: 9960 | X36: 10000 | Y36: 10020 | Z36: 10020 | AA36: 10002 | AB36: 10040 | AC36: 10060 | AD36: 10080 | AE36: 10100 | AF36: 10074 | AG36: 10120 | AH36: 10180 | AI36: 10240 | AJ36: 10264 | AK36: 10200 | AL36: 10266 | AM36: 10286 | AN36: 10306 | AO36: 10324 | AP36: 10296 | AQ36: 10180 | AR36: 10175 | AS36: 10331 | AT36: 10308 | AU36: 10189 | AV36: 10347 | AW36: 10449 | AX36: 10558 | AY36: 10610 | AZ36: 10492 | BA36: 10670 | BB36: 10708 | BC36: 10735 | BD36: =BC36+25 -> 10760 | BE36: =AVERAGE(BA36:BD36) -> 10718.25 | BF36: =BD36+30 -> 10790 | BG36: =BF36+30 -> 10820 | BH36: =BG36+30 -> 10850 | BI36: =BH36+30 -> 10880 | BJ36: =AVERAGE(BF36:BI36) -> 10835 | BK36: =BJ36+120 -> 10955 | BL36: =BK36+120 -> 11075 | BM36: =BL36+120 -> 11195
A38: Growth
A39: Online Stores (yr/yr Growth) | Q39: =Q8/L8-1 -> 0.18954503 | R39: =R8/M8-1 -> 0.14611368 | S39: =S8/N8-1 -> 0.16566886 | T39: =T8/O8-1 -> 0.22241779 | U39: =U8/P8-1 -> 0.19747529 | V39: =V8/Q8-1 -> 0.18508837 | W39: =W8/R8-1 -> 0.18018926 | X39: =X8/S8-1 -> 0.14359687 | ... BJ39: =BJ8/BE8-1 -> 0.05 | BK39: =BK8/BJ8-1 -> 0.05 | BL39: =BL8/BK8-1 -> 0.05 | BM39: =BM8/BL8-1 -> 0.05
A40: Physical Stores (yr/yr Growth) | Y40: =Y9/T9-1 -> 2.3291536 | Z40: =Z9/U9-1 -> -0.026758072 | AA40: =AA9/V9-1 -> 1.9706795 | AB40: =AB9/W9-1 -> 0.01032137 | AC40: =AC9/X9-1 -> 0.004174397 | AD40: =AD9/Y9-1 -> -0.013182674 | AE40: =AE9/Z9-1 -> -0.0086344013 | AF40: =AF9/AA9-1 -> -0.0018578727 | ... BJ40: =BJ9/BE9-1 -> 0.05 | BK40: =BK9/BJ9-1 -> 0.05 | BL40: =BL9/BK9-1 -> 0.05 | BM40: =BM9/BL9-1 -> 0.05
A41: Third-Party Seller Services (yr/yr Growth) | Q41: =Q10/L10-1 -> 0.42931742 | R41: =R10/M10-1 -> 0.34097063 | S41: =S10/N10-1 -> 0.37536888 | T41: =T10/O10-1 -> 0.40268931 | U41: =U10/P10-1 -> 0.41134657 | V41: =V10/Q10-1 -> 0.38656924 | W41: =W10/R10-1 -> 0.43911153 | X41: =X10/S10-1 -> 0.38778429 | ... BJ41: =BJ10/BE10-1 -> 0.1 | BK41: =BK10/BJ10-1 -> 0.1 | BL41: =BL10/BK10-1 -> 0.1 | BM41: =BM10/BL10-1 -> 0.1
A42: Subscription Services (yr/yr Growth) | Q42: =Q11/L11-1 -> 0.43116185 | R42: =R11/M11-1 -> 0.49153846 | S42: =S11/N11-1 -> 0.51292802 | T42: =T11/O11-1 -> 0.59334204 | U42: =U11/P11-1 -> 0.4915493 | V42: =V11/Q11-1 -> 0.52072579 | W42: =W11/R11-1 -> 0.59979371 | X42: =X11/S11-1 -> 0.57413395 | ... BJ42: =BJ11/BE11-1 -> 0.1 | BK42: =BK11/BJ11-1 -> 0.1 | BL42: =BL11/BK11-1 -> 0.1 | BM42: =BM11/BL11-1 -> 0.1
A43: Advertising Services (yr/yr Growth) | AN43: =AN12/AI12-1 -> 0.52790044 | AO43: =AO12/AJ12-1 -> 0.32190476 | AP43: =AP12/AK12-1 -> 1.5267596 | AQ43: =AQ12/AL12-1 -> 0.23444601 | AR43: =AR12/AM12-1 -> 0.17527849 | AS43: =AS12/AN12-1 -> 0.25433526 | AT43: =AT12/AO12-1 -> 0.18948127 | AU43: =AU12/AP12-1 -> 0.21113607 | ... BJ43: =BJ12/BE12-1 -> 0.18 | BK43: =BK12/BJ12-1 -> 0.15 | BL43: =BL12/BK12-1 -> 0.15 | BM43: =BM12/BL12-1 -> 0.15
...

Sheet BS
A1: Amazon.com Inc. (AMZN)
A2: Balance Sheet
A3: In millions except per share data
BD5: Estimates | BE5: Estimates | BF5: Estimates | BG5: Estimates | BH5: Estimates | BI5: Estimates | BJ5: Estimates | BK5: Estimates | BL5: Estimates | BM5: Estimates
E6: 2008 | F6: 2009 | G6: 2010 | H6: 2011 | I6: 2012 | J6: 2013 | K6: 2014 | L6: 2015 | M6: 42460 | N6: 42551 | O6: 42643 | P6: 42735 | Q6: 2016 | R6: 42825 | S6: 42916 | T6: 43008 | U6: 43100 | V6: 2017 | W6: 43190 | X6: 43281 | Y6: 43373 | Z6: 43465 | AA6: 2018 | AB6: 43555 | AC6: 43646 | AD6: 43738 | AE6: 43830 | AF6: 2019 | AG6: 43921 | AH6: 44012 | AI6: 44104 | AJ6: 44196 | AK6: 2020 | AL6: 44286 | AM6: 44377 | AN6: 44469 | AO6: 44561 | AP6: 2021 | AQ6: 44651 | AR6: 44742 | AS6: 44834 | AT6: 44926 | AU6: 2022 | AV6: 45016 | AW6: 45107 | AX6: 45199 | AY6: 45291 | AZ6: 2023 | BA6: 45382 | BB6: 45473 | BC6: 45565 | BD6: 45657 | BE6: 2024 | BF6: 45747 | BG6: 45838 | BH6: 45930 | BI6: 46022 | BJ6: 2025 | BK6: 2026 | BL6: 2027 | BM6: 2028
A8: Cash & Equivalents | E8: 2769 | F8: 3444 | G8: 3777 | H8: 5269 | I8: 8084 | J8: 8658 | K8: 14557 | L8: 15890 | M8: 12470 | N8: 12521 | O8: 13656 | P8: 19334 | Q8: 19334 | R8: 15440 | S8: 13203 | T8: 12767 | U8: 20522 | V8: 20522 | W8: 16676 | X8: 19823 | Y8: 20425 | Z8: 31750 | AA8: 31750 | AB8: 23115 | AC8: 22616 | AD8: 23255 | AE8: 36092 | AF8: 36092 | AG8: 27201 | AH8: 36092 | AI8: 29930 | AJ8: 42122 | AK8: 42122 | AL8: 33834 | AM8: 40380 | AN8: 29944 | AO8: 36220 | AP8: 36220 | AQ8: 36393 | AR8: 37478 | AS8: 34947 | AT8: 53888 | AU8: 53888 | AV8: 49343 | AW8: 49529 | AX8: 49605 | AY8: 73387 | AZ8: 73387 | BA8: 72852 | BB8: 71178 | BC8: 75091 | BD8: =BD32+BD40-BD18-BD9-BD10-BD11 -> 85676.718 | BE8: =BD8 -> 85676.718 | BF8: =BF32+BF40-BF18-BF9-BF10-BF11 -> 88244.539 | BG8: =BG32+BG40-BG18-BG9-BG10-BG11 -> 96981.304 | BH8: =BH32+BH40-BH18-BH9-BH10-BH11 -> 110678.75 | BI8: =BI32+BI40-BI18-BI9-BI10-BI11 -> 119328.85 | BJ8: =BI8 -> 119328.85 | BK8: =BK32+BK40-BK18-BK9-BK10-BK11 -> 162927.4 | BL8: =BL32+BL40-BL18-BL9-BL10-BL11 -> 208523.5 | BM8: =BM32+BM40-BM18-BM9-BM10-BM11 -> 260421.22
A9: Marketable Securities | E9: 958 | F9: 2922 | G9: 4985 | H9: 4307 | I9: 3364 | J9: 3789 | K9: 2859 | L9: 3918 | M9: 3389 | N9: 4019 | O9: 4691 | P9: 6647 | Q9: 6647 | R9: 6091 | S9: 8248 | T9: 11543 | U9: 10464 | V9: 10464 | W9: 8287 | X9: 7227 | Y9: 9340 | Z9: 9500 | AA9: 9500 | AB9: 13905 | AC9: 18847 | AD9: 20146 | AE9: 18929 | AF9: 18929 | AG9: 22091 | AH9: 18929 | AI9: 38472 | AJ9: 42274 | AK9: 42274 | AL9: 39436 | AM9: 49514 | AN9: 49044 | AO9: 59829 | AP9: 59829 | AQ9: 29992 | AR9: 23232 | AS9: 23715 | AT9: 16138 | AU9: 16138 | AV9: 15062 | AW9: 14441 | AX9: 14564 | AY9: 13393 | AZ9: 13393 | BA9: 12222 | BB9: 17914 | BC9: 12960 | BD9: =BC9*(1+'Assumptions + Estimates'!$J$8) -> 13530.24 | BE9: =BD9 -> 13530.24 | BF9: =BE9*(1+'Assumptions + Estimates'!$O$8) -> 13990.268 | BG9: =BF9*(1+'Assumptions + Estimates'!$O$8) -> 14465.937 | BH9: =BG9*(1+'Assumptions + Estimates'!$O$8) -> 14957.779 | BI9: =BH9*(1+'Assumptions + Estimates'!$O$8) -> 15466.344 | BJ9: =BI9 -> 15466.344 | BK9: =BJ9*(1+'Assumptions + Estimates'!$O$8) -> 15992.199 | BL9: =BK9*(1+'Assumptions + Estimates'!$O$8) -> 16535.934 | BM9: =BL9*(1+'Assumptions + Estimates'!$O$8) -> 17098.156
A10: Inventories | E10: 1399 | F10: 2171 | G10: 3202 | H10: 4992 | I10: 6031 | J10: 7411 | K10: 8299 | L10: 10243 | M10: 9582 | N10: 9588 | O10: 10696 | P10: 11461 | Q10: 11461 | R10: 10600 | S10: 11510 | T10: 13711 | U10: 16047 | V10: 16047 | W10: 13840 | X10: 14824 | Y10: 15862 | Z10: 17174 | AA10: 17174 | AB10: 16432 | AC10: 18580 | AD10: 18766 | AE10: 20497 | AF10: 20497 | AG10: 18857 | AH10: 20497 | AI10: 23735 | AJ10: 23795 | AK10: 23795 | AL10: 23849 | AM10: 24119 | AN10: 30933 | AO10: 32640 | AP10: 32640 | AQ10: 34987 | AR10: 38153 | AS10: 36647 | AT10: 34405 | AU10: 34405 | AV10: 34170 | AW10: 36587 | AX10: 35406 | AY10: 33318 | AZ10: 33318 | BA10: 31147 | BB10: 34109 | BC10: 36103 | BD10: =BC10*(1+'Assumptions + Estimates'!$J$7) -> 37041.678 | BE10: =BD10 -> 37041.678 | BF10: =BE10*(1+'Assumptions + Estimates'!$O$7) -> 37819.553 | BG10: =BF10*(1+'Assumptions + Estimates'!$O$7) -> 38613.764 | BH10: =BG10*(1+'Assumptions + Estimates'!$O$7) -> 39424.653 | BI10: =BH10*(1+'Assumptions + Estimates'!$O$7) -> 40252.571 | BJ10: =BI10 -> 40252.571 | BK10: =BJ10*(1+'Assumptions + Estimates'!P7) -> 41057.622 | BL10: =BK10*(1+'Assumptions + Estimates'!Q7) -> 41878.774 | BM10: =BL10*(1+'Assumptions + Estimates'!R7) -> 42716.35
A11: Accounts Receivable, Net, & Other | E11: 827 | F11: 988 | G11: 1587 | H11: 2571 | I11: 3817 | J11: 4767 | K11: 5612 | L11: 5654 | M11: 5072 | N11: 6092 | O11: 6566 | P11: 8339 | Q11: 8339 | R11: 7329 | S11: 8046 | T11: 10557 | U11: 13164 | V11: 13164 | W11: 12026 | X11: 12607 | Y11: 14258 | Z11: 16677 | AA11: 16677 | AB11: 15979 | AC11: 16747 | AD11: 16887 | AE11: 20816 | AF11: 20816 | AG11: 17836 | AH11: 20816 | AI11: 20832 | AJ11: 24542 | AK11: 24542 | AL11: 24289 | AM11: 26835 | AN11: 28610 | AO11: 32891 | AP11: 32891 | AQ11: 32504 | AR11: 34804 | AS11: 36154 | AT11: 42360 | AU11: 42360 | AV11: 37646 | AW11: 39925 | AX11: 43420 | AY11: 52253 | AZ11: 52253 | BA11: 47768 | BB11: 50106 | BC11: 51638 | BD11: =BC11*(AY11/AX11) -> 62142.801 | BE11: =BD11 -> 62142.801 | BF11: =BE11*(BA11/AZ11) -> 56808.936 | BG11: =BF11*(BB11/BA11) -> 59589.443 | BH11: =BG11*(BC11/BB11) -> 61411.401 | BI11: =BH11*(BD11/BC11) -> 73904.421 | BJ11: =BI11 -> 73904.421 | BK11: =BJ11*(BJ11/BE11) -> 87892.135 | BL11: =BK11*(BK11/BJ11) -> 104527.27 | BM11: =BL11*(BL11/BK11) -> 124310.9
A12: Total Current Assets | E12: =SUM(E8:E11) -> 5953 | F12: =SUM(F8:F11) -> 9525 | G12: =SUM(G8:G11) -> 13551 | H12: =SUM(H8:H11) -> 17139 | I12: =SUM(I8:I11) -> 21296 | J12: =SUM(J8:J11) -> 24625 | K12: =SUM(K8:K11) -> 31327 | L12: =SUM(L8:L11) -> 35705 | ... BM12: =SUM(BM8:BM11) -> 444546.62
A14: PP&E | E14: 854 | F14: 1290 | G14: 2414 | H14: 4417 | I14: 7060 | J14: 10949 | K14: 16967 | L14: 21838 | M14: 23308 | N14: 25190 | O14: 27177 | P14: 29114 | Q14: 29114 | R14: 32632 | S14: 37083 | T14: 45335 | U14: 48866 | V14: 48866 | W14: 52331 | X14: 54768 | Y14: 58019 | Z14: 61797 | AA14: 61797 | AB14: 61048 | AC14: 64723 | AD14: 67662 | AE14: 72705 | AF14: 72705 | AG14: 77779 | AH14: 72705 | AI14: 99981 | AJ14: 113114 | AK14: 113114 | AL14: 121461 | AM14: 133502 | AN14: 147152 | AO14: 160281 | AP14: 160281 | AQ14: 168468 | AR14: 173706 | AS14: 177195 | AT14: 186715 | AU14: 186715 | AV14: 190754 | AW14: 193784 | AX14: 196468 | AY14: 204177 | AZ14: 204177 | BA14: 209950 | BB14: 220717 | BC14: 237917 | BD14: =BC14+(-CF!BD22-CF!BD23)-CF!BD9 -> 239987.74 | BE14: =BD14 -> 239987.74 | BF14: =BE14+(-CF!BF22-CF!BF23)-CF!BF9 -> 244856.43 | BG14: =BF14+(-CF!BG22-CF!BG23)-CF!BG9 -> 249704.5 | BH14: =BG14+(-CF!BH22-CF!BH23)-CF!BH9 -> 254298.78 | BI14: =BH14+(-CF!BI22-CF!BI23)-CF!BI9 -> 260543.15 | BJ14: =BI14 -> 260543.15 | BK14: =BJ14+(-CF!BK22-CF!BK23)-CF!BK9 -> 269876.33 | BL14: =BK14+(-CF!BL22-CF!BL23)-CF!BL9 -> 275866.86 | BM14: =BL14+(-CF!BM22-CF!BM23)-CF!BM9 -> 277808.54
A15: Operating Leases | E15: 0 | F15: 0 | G15: 0 | H15: 0 | I15: 0 | J15: 0 | K15: 0 | L15: 0 | M15: 0 | N15: 0 | O15: 0 | P15: 0 | Q15: 0 | R15: 0 | S15: 0 | T15: 0 | U15: 0 | V15: 0 | W15: 0 | X15: 0 | Y15: 0 | Z15: 0 | AA15: 0 | AB15: 20132 | AC15: 21649 | AD15: 23114 | AE15: 25141 | AF15: 25141 | AG15: 26279 | AH15: 25141 | AI15: 34119 | AJ15: 37553 | AK15: 37553 | AL15: 39328 | AM15: 43346 | AN15: 52151 | AO15: 56082 | AP15: 56082 | AQ15: 56161 | AR15: 58430 | AS15: 62033 | AT15: 66123 | AU15: 66123 | AV15: 68262 | AW15: 70332 | AX15: 70758 | AY15: 72513 | AZ15: 72513 | BA15: 73313 | BB15: 74575 | BC15: 76527 | BD15: =BC15*(AY15/AX15) -> 78425.088 | BE15: =BD15 -> 78425.088 | BF15: =BE15*(BA15/AZ15) -> 79290.313 | BG15: =BF15*(BB15/BA15) -> 80655.205 | BH15: =BG15*(BC15/BB15) -> 82766.355 | BI15: =BH15*(BD15/BC15) -> 84819.196 | BJ15: =BI15 -> 84819.196 | BK15: =BJ15*(BJ15/BE15) -> 91734.625 | BL15: =BK15*(BK15/BJ15) -> 99213.879 | BM15: =BL15*(BL15/BK15) -> 107302.93
A16: Goodwill | E16: 438 | F16: 1234 | G16: 1349 | H16: 1955 | I16: 2552 | J16: 2655 | K16: 3319 | L16: 3759 | M16: 3785 | N16: 3774 | O16: 3815 | P16: 3784 | Q16: 3784 | R16: 3823 | S16: 4254 | T16: 13271 | U16: 13350 | V16: 13350 | W16: 13388 | X16: 13944 | Y16: 14553 | Z16: 14548 | AA16: 14548 | AB16: 14708 | AC16: 14727 | AD16: 14734 | AE16: 14754 | AF16: 14754 | AG16: 14739 | AH16: 14754 | AI16: 14960 | AJ16: 15017 | AK16: 15017 | AL16: 15220 | AM16: 15350 | AN16: 15345 | AO16: 15371 | AP16: 15371 | AQ16: 20229 | AR16: 20195 | AS16: 20168 | AT16: 20288 | AU16: 20288 | AV16: 22749 | AW16: 22785 | AX16: 22749 | AY16: 22789 | AZ16: 22789 | BA16: 22770 | BB16: 22879 | BC16: 23081 | BD16: =AVERAGE(BA16:BC16) -> 22910 | BE16: =BD16 -> 22910 | BF16: =AVERAGE(BC16:BE16) -> 22967 | BG16: =AVERAGE(BD16:BF16) -> 22929 | BH16: =AVERAGE(BE16:BG16) -> 22935.333 | BI16: =AVERAGE(BF16:BH16) -> 22943.778 | BJ16: =BI16 -> 22943.778 | BK16: =AVERAGE(BH16:BJ16) -> 22940.963 | BL16: =AVERAGE(BI16:BK16) -> 22942.84 | BM16: =AVERAGE(BJ16:BL16) -> 22942.527
